<?xml version="1.0" encoding="utf-8"?>
<!-- This URDF was automatically created by SolidWorks to URDF Exporter! Originally created by Stephen Brawner (brawner@gmail.com) 
     Commit Version: 1.6.0-4-g7f85cfe  Build Version: 1.6.7995.38578
     For more information, please see http://wiki.ros.org/sw_urdf_exporter -->
<robot name="ors_robot">

  <!-- Base Link -->
  <link name="base_link">
    <inertial>
      <origin xyz="0.0375410289558811 -0.000428988568958566 0.0421956483515309" rpy="0 0 0" />
      <mass value="3.75941738254691" />
      <inertia ixx="0.0302625393343646" ixy="0.000494029605687653" ixz="0.000877895110474979" iyy="0.0183790893714639" iyz="3.90426116410347E-05" izz="0.0454611424589501"/>
    </inertial>
    <visual>
      <origin
        xyz="0 0 0"
        rpy="0 0 0" />
      <geometry>
        <mesh
          filename="file://$(find ors_robot)/meshes/base_link.STL" />
      </geometry>
      <material
        name="">
        <color
          rgba="0.964705882352941 0.964705882352941 0.952941176470588 1" />
      </material>
    </visual>
    <collision>
      <origin
        xyz="0 0 0"
        rpy="0 0 0" />
      <geometry>
        <mesh
          filename="file://$(find ors_robot)/meshes/base_link.STL" />
      </geometry>
    </collision>
  </link>

  <!-- Left Wheel Link -->
  <link name="left_wheel">
    <inertial>
      <origin xyz="3.51874085424697E-12 1.11144426995224E-12 1.99507077525141E-13" rpy="0 0 0" />
      <mass value="0.0610725611857856" />
      <inertia ixx="2.0932620346428E-05" ixy="4.70726299862862E-31" ixz="-2.66341320047295E-16" iyy="2.0932620346428E-05" iyz="-8.67742268246757E-21" izz="3.95750196483891E-05" />
    </inertial>
    <visual>
      <origin xyz="0 0 0" rpy="0 0 0" />
      <geometry>
        <mesh filename="file://$(find ors_robot)/meshes/left_wheel.STL" />
      </geometry>
      <material name="">
        <color rgba="0.792156862745098 0.819607843137255 0.933333333333333 1" />
      </material>
    </visual>
    <collision>
      <origin xyz="0 0 0" rpy="0 0 0" />
      <geometry>
        <mesh filename="file://$(find ors_robot)/meshes/left_wheel.STL" />
      </geometry>
    </collision>
  </link>
  <joint name="left_wheel_joint" type="continuous">
    <origin xyz="-0.0129112176850158 -0.117664217504032 0.025328779706945" rpy="-1.5707963267949 1.5707963267949 0" />
    <parent link="base_link" />
    <child link="left_wheel" />
    <axis xyz="0 0 1" />
    <limit effort="10" velocity="10" />
    <dynamics damping="0.1" friction="0.1" />
  </joint>

  <!-- Right Wheel Link -->
  <link name="right_wheel">
    <inertial>
      <origin xyz="1.58206781009085E-13 1.11127773649855E-12 1.99618099827603E-13" rpy="0 0 0" />
      <mass value="0.0610725611857856" />
      <inertia ixx="2.0932620346428E-05" ixy="3.70181437751706E-31" ixz="-2.66341411820888E-16" iyy="2.0932620346428E-05" iyz="-8.74736255787152E-21" izz="3.95750196483891E-05" />
    </inertial>
    <visual>
      <origin xyz="0 0 0" rpy="0 0 0" />
      <geometry>
        <mesh filename="file://$(find ors_robot)/meshes/right_wheel.STL" />
      </geometry>
      <material name="">
        <color rgba="0.792156862745098 0.819607843137255 0.933333333333333 1" />
      </material>
    </visual>
    <collision>
      <origin
        xyz="0 0 0"
        rpy="0 0 0" />
      <geometry>
        <mesh
          filename="file://$(find ors_robot)/meshes/right_wheel.STL" />
      </geometry>
    </collision>
  </link>
  <joint name="right_wheel_joint" type="continuous">
    <origin xyz="-0.0129112176873895 0.117549999993357 0.025328779706945" rpy="-1.5707963267949 1.5707963267949 0" />
    <parent link="base_link" />
    <child link="right_wheel" />
    <axis xyz="0 0 1" />
    <limit effort="10" velocity="10" />
    <dynamics damping="0.1" friction="0.1" />
  </joint>

  <!-- Front Wheel Link -->
  <link name="front_wheel">
    <inertial>
      <origin xyz="1.76092473935796E-12 1.50951473543159E-12 1.99518179755387E-12" rpy="0 0 0" />
      <mass value="0.00785398163397449" />
      <inertia ixx="6.05411084285534E-07" ixy="4.0573618672563E-33" ixz="3.03941757673171E-18" iyy="6.05411084285534E-07" iyz="-1.54167304373854E-22" izz="3.92699081698725E-07" />
    </inertial>
    <visual>
      <origin xyz="0 0 0" rpy="0 0 0" />
      <geometry>
        <mesh filename="file://$(find ors_robot)/meshes/front_wheel.STL" />
      </geometry>
      <material name="">
        <color rgba="0.792156862745098 0.819607843137255 0.933333333333333 1" />
      </material>
    </visual>
    <collision>
      <origin xyz="0 0 0" rpy="0 0 0" />
      <geometry>
        <mesh filename="file://$(find ors_robot)/meshes/front_wheel.STL" />
      </geometry>
    </collision>
  </link>
  <joint name="front_wheel_joint" type="continuous">
    <origin xyz="0.112773589774212 5.4823545785343E-05 0.00132877970694717" rpy="-1.5707963267949 0 0" />
    <parent link="base_link" />
    <child link="front_wheel" />
    <axis xyz="0 0 -1" />
    <limit effort="10" velocity="10" />
    <dynamics damping="0" friction="0" />
  </joint>

  <!-- Plate Link -->
  <link name="plate">
    <inertial>
      <origin xyz="8.77742323268649E-13 -4.02533781196368E-07 -0.00402127109268191" rpy="0 0 0" />
      <mass value="0.391942695372502" />
      <inertia ixx="0.002124680445083" ixy="3.21655738947554E-16" ixz="-3.65115980107875E-17" iyy="0.00211257768873928" iyz="-1.8488967635126E-23" izz="0.00421569304990099" />
    </inertial>
    <visual>
      <origin xyz="0 0 0" rpy="0 0 0" />
      <geometry>
        <mesh filename="file://$(find ors_robot)/meshes/plate.STL" />
      </geometry>
      <material name="">
        <color rgba="0.792156862745098 0.819607843137255 0.933333333333333 1" />
      </material>
    </visual>
    <collision>
      <origin xyz="0 0 0" rpy="0 0 0" />
      <geometry>
        <mesh filename="file://$(find ors_robot)/meshes/plate.STL" />
      </geometry>
    </collision>
  </link>
  <joint name="plate" type="fixed">
    <origin xyz="-0.0127165282933757 3.07436914599446E-05 0.239828779706945" rpy="0 0 0" />
    <parent link="base_link" />
    <child link="plate" />
    <axis xyz="0 0 0" />
  </joint>
</robot>
